<?xml version="1.0" encoding="utf-8"?>
<!-- This URDF was automatically created by SolidWorks to URDF Exporter! Originally created by Stephen Brawner (brawner@gmail.com) 
     Commit Version: 1.6.0-4-g7f85cfe  Build Version: 1.6.7995.38578
     For more information, please see http://wiki.ros.org/sw_urdf_exporter -->
<robot xmlns:xacro="http://www.ros.org/wiki/xacro">


<!-- BASE LINK -->

  <link name="world"></link>

  <joint name="world_joint" type="fixed">
      <parent link="world"/>
      <child link="L_0_link"/>
      <origin xyz="0.5 0.5 0" rpy="0 0 0"/>
  </joint>

<!-- BIPO LINK -->

  <link
    name="L_0_link">
    <inertial>
      <origin
        xyz="0 0 0"
        rpy="0 0 0" />
      <mass
        value="2.5217" />
      <inertia
        ixx="0.010603"
        ixy="0"
        ixz="0"
        iyy="0.010603"
        iyz="0"
        izz="0.017663" />
    </inertial>
    <visual>
      <origin
        xyz="0 0 0"
        rpy="0 0 0" />
      <geometry>
        <mesh
          filename="package://simu_bipo/meshes/L_0_link.STL" />
      </geometry>
      <material
        name="">
        <color
          rgba="0.75294 0.75294 0.75294 1" />
      </material>
    </visual>
    <collision>
      <origin
        xyz="0 0 0"
        rpy="0 0 0" />
      <geometry>
        <mesh
          filename="package://simu_bipo/meshes/L_0_link.STL" />
      </geometry>
    </collision>
  </link>
  <link
    name="L_7_link">
    <inertial>
      <origin
        xyz="0 0 0.0035198"
        rpy="0 0 0" />
      <mass
        value="0.58585" />
      <inertia
        ixx="0.00040384"
        ixy="0"
        ixz="0"
        iyy="0.00049201"
        iyz="0"
        izz="0.00021964" />
    </inertial>
    <visual>
      <origin
        xyz="0 0 0"
        rpy="0 0 0" />
      <geometry>
        <mesh
          filename="package://simu_bipo/meshes/L_7_link.STL" />
      </geometry>
      <material
        name="">
        <color
          rgba="0.75294 0.75294 0.75294 1" />
      </material>
    </visual>
    <collision>
      <origin
        xyz="0 0 0"
        rpy="0 0 0" />
      <geometry>
        <mesh
          filename="package://simu_bipo/meshes/L_7_link.STL" />
      </geometry>
    </collision>
  </link>
  <joint
    name="L7_L0_joint"
    type="continuous">
    <origin
      xyz="0 0 0.17735"
      rpy="0 0 3.1416" />
    <parent
      link="L_0_link" />
    <child
      link="L_7_link" />
    <axis
      xyz="0 0 1" />
    <limit
      lower="0"
      upper="0"
      effort="100"
      velocity="100" />
    <dynamics
      damping="0.1"
      friction="0.1" />
  </joint>
  <link
    name="L_6_link">
    <inertial>
      <origin
        xyz="-0.01046 0.030187 2.4457E-05"
        rpy="0 0 0" />
      <mass
        value="6.2077" />
      <inertia
        ixx="0.014538"
        ixy="0"
        ixz="0"
        iyy="0.18457"
        iyz="0"
        izz="0.18422" />
    </inertial>
    <visual>
      <origin
        xyz="0 0 0"
        rpy="0 0 0" />
      <geometry>
        <mesh
          filename="package://simu_bipo/meshes/L_6_link.STL" />
      </geometry>
      <material
        name="">
        <color
          rgba="0.75294 0.75294 0.75294 1" />
      </material>
    </visual>
    <collision>
      <origin
        xyz="0 0 0"
        rpy="0 0 0" />
      <geometry>
        <mesh
          filename="package://simu_bipo/meshes/L_6_link.STL" />
      </geometry>
    </collision>
  </link>
  <joint
    name="L6_L7_joint"
    type="continuous">
    <origin
      xyz="-5E-05 0 0.06"
      rpy="1.5708 -0.033161 1.5708" />
    <parent
      link="L_7_link" />
    <child
      link="L_6_link" />
    <axis
      xyz="0 0 1" />
    <limit
      lower="0"
      upper="0"
      effort="100"
      velocity="100" />
    <dynamics
      damping="0.1"
      friction="0.1" />
  </joint>
  <link
    name="L_3_link">
    <inertial>
      <origin
        xyz="0.0087332 0.094445 0.11407"
        rpy="0 0 0" />
      <mass
        value="4.7184" />
      <inertia
        ixx="0.0083251"
        ixy="0.0000166"
        ixz="0.00164"
        iyy="0.0070716"
        iyz="0.0000431"
        izz="0.0055434" />
    </inertial>
    <visual>
      <origin
        xyz="0 0 0"
        rpy="0 0 0" />
      <geometry>
        <mesh
          filename="package://simu_bipo/meshes/L_3_link.STL" />
      </geometry>
      <material
        name="">
        <color
          rgba="0.75294 0.75294 0.75294 1" />
      </material>
    </visual>
    <collision>
      <origin
        xyz="0 0 0"
        rpy="0 0 0" />
      <geometry>
        <mesh
          filename="package://simu_bipo/meshes/L_3_link.STL" />
      </geometry>
    </collision>
  </link>
  <joint
    name="L3_L6_joint"
    type="continuous">
    <origin
      xyz="1.572 0.0325 0"
      rpy="0.033161 1.5708 0" />
    <parent
      link="L_6_link" />
    <child
      link="L_3_link" />
    <axis
      xyz="0 0 1" />
    <limit
      lower="0"
      upper="0"
      effort="100"
      velocity="100" />
    <dynamics
      damping="0.1"
      friction="0.1" />
  </joint>
  <link
    name="L_4_link">
    <inertial>
      <origin
        xyz="0.00078736 -0.065737 0.044105"
        rpy="0 0 0" />
      <mass
        value="1.1717" />
      <inertia
        ixx="0.00046552"
        ixy="-0.0000180"
        ixz="0.0000024"
        iyy="0.00031569"
        iyz="0.0000024"
        izz="0.00042903" />
    </inertial>
    <visual>
      <origin
        xyz="0 0 0"
        rpy="0 0 0" />
      <geometry>
        <mesh
          filename="package://simu_bipo/meshes/L_4_link.STL" />
      </geometry>
      <material
        name="">
        <color
          rgba="0.75294 0.75294 0.75294 1" />
      </material>
    </visual>
    <collision>
      <origin
        xyz="0 0 0"
        rpy="0 0 0" />
      <geometry>
        <mesh
          filename="package://simu_bipo/meshes/L_4_link.STL" />
      </geometry>
    </collision>
  </link>
  <joint
    name="L4_L3_joint"
    type="continuous">
    <origin
      xyz="0 -0.0016127 0.14743"
      rpy="-0.033161 0 0" />
    <parent
      link="L_3_link" />
    <child
      link="L_4_link" />
    <axis
      xyz="0 0 1" />
    <limit
      lower="0"
      upper="0"
      effort="100"
      velocity="100" />
    <dynamics
      damping="0.1"
      friction="0.1" />
  </joint>
  <link
    name="L_5_link">
    <inertial>
      <origin
        xyz="3.4552E-06 -0.061983 -2.3007E-10"
        rpy="0 0 0" />
      <mass
        value="0.23479" />
      <inertia
        ixx="0.0000504"
        ixy="0"
        ixz="0"
        iyy="0.0000232"
        iyz="0"
        izz="0.0000493" />
    </inertial>
    <visual>
      <origin
        xyz="0 0 0"
        rpy="0 0 0" />
      <geometry>
        <mesh
          filename="package://simu_bipo/meshes/L_5_link.STL" />
      </geometry>
      <material
        name="">
        <color
          rgba="0.75294 0.75294 0.75294 1" />
      </material>
    </visual>
    <collision>
      <origin
        xyz="0 0 0"
        rpy="0 0 0" />
      <geometry>
        <mesh
          filename="package://simu_bipo/meshes/L_5_link.STL" />
      </geometry>
    </collision>
  </link>
  <joint
    name="L5_L4_joint"
    type="continuous">
    <origin
      xyz="0 -0.1575 -5E-05"
      rpy="0 0 0" />
    <parent
      link="L_4_link" />
    <child
      link="L_5_link" />
    <axis
      xyz="0 0 1" />
    <limit
      lower="0"
      upper="0"
      effort="100"
      velocity="100" />
    <dynamics
      damping="0.1"
      friction="0.1" />
  </joint>
  <link
    name="L_2_link">
    <inertial>
      <origin
        xyz="-0.00078736 -0.067164 -0.041901"
        rpy="0 0 0" />
      <mass
        value="1.1717" />
      <inertia
        ixx="0.00046552"
        ixy="0.0000181"
        ixz="0.0000018"
        iyy="0.00031566"
        iyz="0.0000013"
        izz="0.00042907" />
    </inertial>
    <visual>
      <origin
        xyz="0 0 0"
        rpy="0 0 0" />
      <geometry>
        <mesh
          filename="package://simu_bipo/meshes/L_2_link.STL" />
      </geometry>
      <material
        name="">
        <color
          rgba="0.75294 0.75294 0.75294 1" />
      </material>
    </visual>
    <collision>
      <origin
        xyz="0 0 0"
        rpy="0 0 0" />
      <geometry>
        <mesh
          filename="package://simu_bipo/meshes/L_2_link.STL" />
      </geometry>
    </collision>
  </link>
  <joint
    name="L2_L3_joint"
    type="continuous">
    <origin
      xyz="0 -0.0037711 0.08237"
      rpy="0 0 0" />
    <parent
      link="L_3_link" />
    <child
      link="L_2_link" />
    <axis
      xyz="0 0 1" />
    <limit
      lower="0"
      upper="0"
      effort="100"
      velocity="100" />
    <dynamics
      damping="0.1"
      friction="0.1" />
  </joint>
  <link
    name="L_1_link">
    <inertial>
      <origin
        xyz="3.4552E-06 -0.061983 -2.3007E-10"
        rpy="0 0 0" />
      <mass
        value="0.23479" />
      <inertia
        ixx="0.0000504"
        ixy="0"
        ixz="0"
        iyy="0.0000232"
        iyz="0"
        izz="0.0000493" />
    </inertial>
    <visual>
      <origin
        xyz="0 0 0"
        rpy="0 0 0" />
      <geometry>
        <mesh
          filename="package://simu_bipo/meshes/L_1_link.STL" />
      </geometry>
      <material
        name="">
        <color
          rgba="0.75294 0.75294 0.75294 1" />
      </material>
    </visual>
    <collision>
      <origin
        xyz="0 0 0"
        rpy="0 0 0" />
      <geometry>
        <mesh
          filename="package://simu_bipo/meshes/L_1_link.STL" />
      </geometry>
    </collision>
  </link>
  <joint
    name="L1_L2_joint"
    type="continuous">
    <origin
      xyz="0 -0.15741 0.0052719"
      rpy="-0.033161 0 0" />
    <parent
      link="L_2_link" />
    <child
      link="L_1_link" />
    <axis
      xyz="0 0 1" />
    <limit
      lower="0"
      upper="0"
      effort="100"
      velocity="100" />
    <dynamics
      damping="0.1"
      friction="0.1" />
  </joint>

</robot>